WARNING 2013-11-19 15:07:51 D:\python\lib\site-packages\django\core\handlers\base.py base 146 Not Found: /account/loggin status_code:404
WARNING 2013-11-19 15:07:54 D:\python\lib\site-packages\django\core\handlers\base.py base 146 Not Found: /account/loggin„ÄÅ status_code:404
WARNING 2013-11-19 15:07:56 D:\python\lib\site-packages\django\core\handlers\base.py base 146 Not Found: /account/loggin/ status_code:404
ERROR 2013-11-19 15:08:38 D:\python\lib\site-packages\django\core\handlers\base.py base 212 Internal Server Error: /account/loggedin/ status_code:500
Traceback (most recent call last):
  File "D:\python\lib\site-packages\django\core\handlers\base.py", line 115, in get_response
    response = callback(request, *callback_args, **callback_kwargs)
  File "D:\eclipse\code\pinloveweb\pinloveweb\views.py", line 81, in loggedin
    userProfile=UserProfile.objects.get(user_id=request.user.id)
  File "D:\python\lib\site-packages\django\db\models\manager.py", line 143, in get
    return self.get_query_set().get(*args, **kwargs)
  File "D:\python\lib\site-packages\django\db\models\query.py", line 389, in get
    (self.model._meta.object_name, kwargs))
DoesNotExist: UserProfile matching query does not exist. Lookup parameters were {'user_id': None}
WARNING 2013-11-19 15:11:52 D:\python\lib\site-packages\django\middleware\csrf.py csrf 186 Forbidden (CSRF token missing or incorrect.): /account/auth/ status_code:403
WARNING 2013-11-19 15:12:54 D:\python\lib\site-packages\django\middleware\csrf.py csrf 186 Forbidden (CSRF token missing or incorrect.): /account/auth/ status_code:403
WARNING 2013-11-19 15:14:15 D:\python\lib\site-packages\django\middleware\csrf.py csrf 186 Forbidden (CSRF token missing or incorrect.): /account/auth/ status_code:403
WARNING 2013-11-19 15:17:58 D:\python\lib\site-packages\django\middleware\csrf.py csrf 186 Forbidden (CSRF token missing or incorrect.): /account/auth/ status_code:403
WARNING 2013-11-19 15:25:19 D:\python\lib\site-packages\django\middleware\csrf.py csrf 186 Forbidden (CSRF token missing or incorrect.): /account/auth/ status_code:403
WARNING 2013-11-19 15:25:34 D:\python\lib\site-packages\django\middleware\csrf.py csrf 186 Forbidden (CSRF token missing or incorrect.): /account/auth/ status_code:403
WARNING 2013-11-19 15:26:52 D:\python\lib\site-packages\django\middleware\csrf.py csrf 186 Forbidden (CSRF token missing or incorrect.): /account/auth/ status_code:403
WARNING 2013-11-19 15:27:19 D:\python\lib\site-packages\django\middleware\csrf.py csrf 186 Forbidden (CSRF token missing or incorrect.): /account/auth/ status_code:403
WARNING 2013-11-19 15:30:00 D:\python\lib\site-packages\django\middleware\csrf.py csrf 186 Forbidden (CSRF token missing or incorrect.): /account/auth/ status_code:403
ERROR 2013-11-20 14:27:49 D:\python\lib\site-packages\django\core\handlers\base.py base 212 Internal Server Error: /account/auth/ status_code:500
Traceback (most recent call last):
  File "D:\python\lib\site-packages\django\core\handlers\base.py", line 115, in get_response
    response = callback(request, *callback_args, **callback_kwargs)
  File "D:\eclipse\code\pinloveweb\pinloveweb\views.py", line 56, in auth_view
    user = auth.authenticate(username=username, password=password)
  File "D:\python\lib\site-packages\django\contrib\auth\__init__.py", line 59, in authenticate
    user = backend.authenticate(**credentials)
  File "D:\python\lib\site-packages\django\contrib\auth\backends.py", line 16, in authenticate
    user = UserModel._default_manager.get_by_natural_key(username)
  File "D:\python\lib\site-packages\django\contrib\auth\models.py", line 168, in get_by_natural_key
    return self.get(**{self.model.USERNAME_FIELD: username})
  File "D:\python\lib\site-packages\django\db\models\manager.py", line 143, in get
    return self.get_query_set().get(*args, **kwargs)
  File "D:\python\lib\site-packages\django\db\models\query.py", line 382, in get
    num = len(clone)
  File "D:\python\lib\site-packages\django\db\models\query.py", line 90, in __len__
    self._result_cache = list(self.iterator())
  File "D:\python\lib\site-packages\django\db\models\query.py", line 301, in iterator
    for row in compiler.results_iter():
  File "D:\python\lib\site-packages\django\db\models\sql\compiler.py", line 775, in results_iter
    for rows in self.execute_sql(MULTI):
  File "D:\python\lib\site-packages\django\db\models\sql\compiler.py", line 839, in execute_sql
    cursor = self.connection.cursor()
  File "D:\python\lib\site-packages\django\db\backends\__init__.py", line 324, in cursor
    cursor = self.make_debug_cursor(self._cursor())
  File "D:\python\lib\site-packages\django\db\backends\mysql\base.py", line 405, in _cursor
    self.connection = Database.connect(**kwargs)
  File "D:\python\lib\site-packages\MySQLdb\__init__.py", line 81, in Connect
    return Connection(*args, **kwargs)
  File "D:\python\lib\site-packages\MySQLdb\connections.py", line 187, in __init__
    super(Connection, self).__init__(*args, **kwargs2)
OperationalError: (1045, "Access denied for user 'root'@'localhost' (using password: YES)")
WARNING 2013-11-20 14:28:20 D:\python\lib\site-packages\django\core\handlers\base.py base 146 Not Found: /the_people_nearby status_code:404
WARNING 2013-11-20 14:29:19 D:\python\lib\site-packages\django\core\handlers\base.py base 146 Not Found: /user/hobby_interest/ status_code:404
