ERROR 2013-12-18 09:48:24 D:\python\lib\site-packages\django\core\handlers\base.py base 212 Internal Server Error: /third_party_login/twitter_login_url/ status_code:500
Traceback (most recent call last):
  File "D:\python\lib\site-packages\django\core\handlers\base.py", line 115, in get_response
    response = callback(request, *callback_args, **callback_kwargs)
  File "D:/eclipse/code/pinloveweb\apps\third_party_login_app\views.py", line 183, in twitter_login_url
    auth = twitter.get_authentication_tokens(callback_url=TWITTER_CALLBACK_URL)
  File "D:/eclipse/code/pinloveweb\apps\third_party_login_app\twython\api.py", line 269, in get_authentication_tokens
    response = self.client.get(self.request_token_url, params=request_args)
  File "D:\python\lib\site-packages\requests\sessions.py", line 394, in get
    return self.request('GET', url, **kwargs)
  File "D:\python\lib\site-packages\requests\sessions.py", line 382, in request
    resp = self.send(prep, **send_kwargs)
  File "D:\python\lib\site-packages\requests\sessions.py", line 485, in send
    r = adapter.send(request, **kwargs)
  File "D:\python\lib\site-packages\requests\adapters.py", line 372, in send
    raise ConnectionError(e)
ConnectionError: HTTPSConnectionPool(host='api.twitter.com', port=443): Max retries exceeded with url: /oauth/request_token?oauth_callback=http%3A%2F%2Fsnailjin.eicp.net%2Fthird_party_login%2Ftwitter_login%2F (Caused by <class 'socket.error'>: [Errno 10053] )
ERROR 2013-12-18 09:48:29 D:\python\lib\site-packages\django\core\handlers\base.py base 212 Internal Server Error: /third_party_login/twitter_login_url/ status_code:500
Traceback (most recent call last):
  File "D:\python\lib\site-packages\django\core\handlers\base.py", line 115, in get_response
    response = callback(request, *callback_args, **callback_kwargs)
  File "D:/eclipse/code/pinloveweb\apps\third_party_login_app\views.py", line 183, in twitter_login_url
    auth = twitter.get_authentication_tokens(callback_url=TWITTER_CALLBACK_URL)
  File "D:/eclipse/code/pinloveweb\apps\third_party_login_app\twython\api.py", line 269, in get_authentication_tokens
    response = self.client.get(self.request_token_url, params=request_args)
  File "D:\python\lib\site-packages\requests\sessions.py", line 394, in get
    return self.request('GET', url, **kwargs)
  File "D:\python\lib\site-packages\requests\sessions.py", line 382, in request
    resp = self.send(prep, **send_kwargs)
  File "D:\python\lib\site-packages\requests\sessions.py", line 485, in send
    r = adapter.send(request, **kwargs)
  File "D:\python\lib\site-packages\requests\adapters.py", line 372, in send
    raise ConnectionError(e)
ConnectionError: HTTPSConnectionPool(host='api.twitter.com', port=443): Max retries exceeded with url: /oauth/request_token?oauth_callback=http%3A%2F%2Fsnailjin.eicp.net%2Fthird_party_login%2Ftwitter_login%2F (Caused by <class 'socket.error'>: [Errno 10053] )
ERROR 2013-12-18 09:48:47 D:\python\lib\site-packages\django\core\handlers\base.py base 212 Internal Server Error: /third_party_login/twitter_login_url/ status_code:500
Traceback (most recent call last):
  File "D:\python\lib\site-packages\django\core\handlers\base.py", line 115, in get_response
    response = callback(request, *callback_args, **callback_kwargs)
  File "D:/eclipse/code/pinloveweb\apps\third_party_login_app\views.py", line 183, in twitter_login_url
    auth = twitter.get_authentication_tokens(callback_url=TWITTER_CALLBACK_URL)
  File "D:/eclipse/code/pinloveweb\apps\third_party_login_app\twython\api.py", line 269, in get_authentication_tokens
    response = self.client.get(self.request_token_url, params=request_args)
  File "D:\python\lib\site-packages\requests\sessions.py", line 394, in get
    return self.request('GET', url, **kwargs)
  File "D:\python\lib\site-packages\requests\sessions.py", line 382, in request
    resp = self.send(prep, **send_kwargs)
  File "D:\python\lib\site-packages\requests\sessions.py", line 485, in send
    r = adapter.send(request, **kwargs)
  File "D:\python\lib\site-packages\requests\adapters.py", line 372, in send
    raise ConnectionError(e)
ConnectionError: HTTPSConnectionPool(host='api.twitter.com', port=443): Max retries exceeded with url: /oauth/request_token?oauth_callback=http%3A%2F%2Fsnailjin.eicp.net%2Fthird_party_login%2Ftwitter_login%2F (Caused by <class 'socket.error'>: [Errno 10053] )
ERROR 2013-12-18 10:35:34 D:\python\lib\site-packages\django\core\handlers\base.py base 212 Internal Server Error: /third_party_login/twitter_login/ status_code:500
Traceback (most recent call last):
  File "D:\python\lib\site-packages\django\core\handlers\base.py", line 115, in get_response
    response = callback(request, *callback_args, **callback_kwargs)
  File "D:/eclipse/code/pinloveweb\apps\third_party_login_app\views.py", line 195, in twitter_login
    twitter = Twython(TwitterConsumerKey, TwitterConsumerSecret,request.session['OAUTH_TOKEN'],request.session['OAUTH_TOKEN_SECRET'])
  File "D:\python\lib\site-packages\django\contrib\sessions\backends\base.py", line 46, in __getitem__
    return self._session[key]
KeyError: 'OAUTH_TOKEN'
ERROR 2013-12-18 11:05:45 D:\python\lib\site-packages\django\core\handlers\base.py base 212 Internal Server Error: /third_party_login/twitter_login_url/ status_code:500
Traceback (most recent call last):
  File "D:\python\lib\site-packages\django\core\handlers\base.py", line 115, in get_response
    response = callback(request, *callback_args, **callback_kwargs)
  File "D:/eclipse/code/pinloveweb\apps\third_party_login_app\views.py", line 183, in twitter_login_url
    auth = twitter.get_authentication_tokens(callback_url=TWITTER_CALLBACK_URL)
  File "D:/eclipse/code/pinloveweb\apps\third_party_login_app\twython\api.py", line 269, in get_authentication_tokens
    response = self.client.get(self.request_token_url, params=request_args)
  File "D:\python\lib\site-packages\requests\sessions.py", line 394, in get
    return self.request('GET', url, **kwargs)
  File "D:\python\lib\site-packages\requests\sessions.py", line 382, in request
    resp = self.send(prep, **send_kwargs)
  File "D:\python\lib\site-packages\requests\sessions.py", line 485, in send
    r = adapter.send(request, **kwargs)
  File "D:\python\lib\site-packages\requests\adapters.py", line 372, in send
    raise ConnectionError(e)
ConnectionError: HTTPSConnectionPool(host='api.twitter.com', port=443): Max retries exceeded with url: /oauth/request_token?oauth_callback=http%3A%2F%2Fsnailjin.eicp.net%2Fthird_party_login%2Ftwitter_login%2F (Caused by <class 'socket.error'>: [Errno 10060] )
WARNING 2013-12-18 11:05:45 D:\python\lib\site-packages\django\core\handlers\base.py base 146 Not Found: /favicon.ico status_code:404
WARNING 2013-12-18 11:05:45 D:\python\lib\site-packages\django\core\handlers\base.py base 146 Not Found: /favicon.ico status_code:404
WARNING 2013-12-18 11:05:45 D:\python\lib\site-packages\django\core\handlers\base.py base 146 Not Found: /favicon.ico status_code:404
ERROR 2013-12-18 11:36:47 D:\python\lib\site-packages\django\core\handlers\base.py base 212 Internal Server Error: /third_party_login/twitter_login/ status_code:500
Traceback (most recent call last):
  File "D:\python\lib\site-packages\django\core\handlers\base.py", line 115, in get_response
    response = callback(request, *callback_args, **callback_kwargs)
  File "D:/eclipse/code/pinloveweb\apps\third_party_login_app\views.py", line 195, in twitter_login
    twitter = Twython(TwitterConsumerKey, TwitterConsumerSecret,request.session['OAUTH_TOKEN'],request.session['OAUTH_TOKEN_SECRET'])
  File "D:\python\lib\site-packages\django\contrib\sessions\backends\base.py", line 46, in __getitem__
    return self._session[key]
KeyError: 'OAUTH_TOKEN'
